<?xml version="1.0" encoding="utf-8"?>
<!-- This URDF was automatically created by SolidWorks to URDF Exporter! Originally created by Stephen Brawner (brawner@gmail.com) 
     Commit Version: 1.6.0-4-g7f85cfe  Build Version: 1.6.7995.38578
     For more information, please see http://wiki.ros.org/sw_urdf_exporter -->
<robot
  name="tibbs">

  <link name="base_link"/>

  <link
    name="chassis_link">
    <inertial>
      <origin
        xyz="0.901693363659599 1.28432197617336 1.61158207376332"
        rpy="0 0 0" />
      <mass
        value="3.11814269963663" />
      <inertia
        ixx="0.00909837052596785"
        ixy="-1.6463950368828E-09"
        ixz="0.00145888599511852"
        iyy="0.189358452797131"
        iyz="-3.00782780425648E-10"
        izz="0.189921112151923" />
    </inertial>
    <visual>
      <origin
        xyz="0 0 0"
        rpy="0 0 0" />
      <geometry>
        <mesh
          filename="file://$(find description)/meshes/base_link.STL" />
      </geometry>
      <material
        name="">
        <color
          rgba="0.250980392156863 0.250980392156863 0.250980392156863 1" />
      </material>
    </visual>
    <collision>
      <origin
        xyz="0 0 0"
        rpy="0 0 0" />
      <geometry>
        <mesh
          filename="file://$(find description)/meshes/base_link.STL" />
      </geometry>
    </collision>
  </link>
  <joint
    name="chassis"
    type="fixed">
    <origin
      xyz="0 0 0"
      rpy="0 0 0" />
    <parent
      link="base_link" />
    <child
      link="chassis_link" />
  </joint>

  <link
    name="LKraken_Link">
    <inertial>
      <origin
        xyz="0 4.44089209850063E-16 -0.0444499999999997"
        rpy="0 0 0" />
      <mass
        value="0.0205241126775189" />
      <inertia
        ixx="4.68663630316243E-05"
        ixy="-1.5972857628399E-21"
        ixz="5.15462132518449E-20"
        iyy="4.68663630316243E-05"
        iyz="2.4910712334582E-19"
        izz="4.91647962426068E-07" />
    </inertial>
    <visual>
      <origin
        xyz="0 0 0"
        rpy="0 0 0" />
      <geometry>
        <mesh
          filename="file://$(find description)/meshes/LKraken_Link.STL" />
      </geometry>
      <material
        name="">
        <color
          rgba="0.792156862745098 0.819607843137255 0.933333333333333 1" />
      </material>
    </visual>
    <collision>
      <origin
        xyz="0 0 0"
        rpy="0 0 0" />
      <geometry>
        <mesh
          filename="file://$(find description)/meshes/LKraken_Link.STL" />
      </geometry>
    </collision>
  </link>
  <joint
    name="LKrakenRotate"
    type="continuous">
    <origin
      xyz="1.1775 -1.6339 1.6133"
      rpy="0 0 -3.1413" />
    <parent
      link="chassis_link" />
    <child
      link="LKraken_Link" />
    <axis xyz="0 0 1"/>
      
  </joint>
  <link
    name="RKraken_Link">
    <inertial>
      <origin
        xyz="0 2.22044604925031E-16 -0.0444499999999999"
        rpy="0 0 0" />
      <mass
        value="0.0205241126775188" />
      <inertia
        ixx="4.68663630316242E-05"
        ixy="-5.81507970624778E-22"
        ixz="7.76950890491656E-22"
        iyy="4.68663630316242E-05"
        iyz="-2.75966965309531E-20"
        izz="4.91647962426068E-07" />
    </inertial>
    <visual>
      <origin
        xyz="0 0 0"
        rpy="0 0 0" />
      <geometry>
        <mesh
          filename="file://$(find description)/meshes/RKraken_Link.STL" />
      </geometry>
      <material
        name="">
        <color
          rgba="0.792156862745098 0.819607843137255 0.933333333333333 1" />
      </material>
    </visual>
    <collision>
      <origin
        xyz="0 0 0"
        rpy="0 0 0" />
      <geometry>
        <mesh
          filename="file://$(find description)/meshes/RKraken_Link.STL" />
      </geometry>
    </collision>
  </link>
  <joint
    name="RKrakenRotate"
    type="continuous">
    <origin
      xyz="1.1775 -1.6339 1.0442"
      rpy="0 0 -3.1413" />
    <parent
      link="chassis_link" />
    <child
      link="RKraken_Link" />
    <axis xyz="0 0 1"/>
      
  </joint>
  <link
    name="LA_Link">
    <inertial>
      <origin
        xyz="-0.0172681243630317 -0.116440645758096 0.212737229814056"
        rpy="0 0 0" />
      <mass
        value="0.970234028410671" />
      <inertia
        ixx="0.00819569952353814"
        ixy="0.00082815317174428"
        ixz="-1.42662335730096E-06"
        iyy="0.000699830914870434"
        iyz="3.45710523187824E-06"
        izz="0.00867844294735176" />
    </inertial>
    <visual>
      <origin
        xyz="0 0 0"
        rpy="0 0 0" />
      <geometry>
        <mesh
          filename="file://$(find description)/meshes/LA_Link.STL" />
      </geometry>
      <material
        name="">
        <color
          rgba="0.792156862745098 0.819607843137255 0.933333333333333 1" />
      </material>
    </visual>
    <collision>
      <origin
        xyz="0 0 0"
        rpy="0 0 0" />
      <geometry>
        <mesh
          filename="file://$(find description)/meshes/LA_Link.STL" />
      </geometry>
    </collision>
  </link>
  <joint
    name="BLARotate"
    type="revolute">
    <origin
      xyz="0.56252 -1.6364 1.0715"
      rpy="0 0 0.88895" />
    <parent
      link="chassis_link" />
    <child
      link="LA_Link" />
    <axis xyz="0 0 1"/>
    <limit
      lower="0"
      upper="0"
      effort="0"
      velocity="0" />
  </joint>
  <link
    name="LAExtend_Link">
    <inertial>
      <origin
        xyz="0.0420523159099391 0.0218514549059925 3.83189571184772E-08"
        rpy="0 0 0" />
      <mass
        value="0.0898377249563414" />
      <inertia
        ixx="0.000634301272313686"
        ixy="-3.23718441672287E-11"
        ixz="-1.23742704912369E-10"
        iyy="4.44119295047458E-06"
        iyz="1.42114602862497E-10"
        izz="0.000634330189167566" />
    </inertial>
    <visual>
      <origin
        xyz="0 0 0"
        rpy="0 0 0" />
      <geometry>
        <mesh
          filename="file://$(find description)/meshes/LAExtend_Link.STL" />
      </geometry>
      <material
        name="">
        <color
          rgba="0.792156862745098 0.819607843137255 0.933333333333333 1" />
      </material>
    </visual>
    <collision>
      <origin
        xyz="0 0 0"
        rpy="0 0 0" />
      <geometry>
        <mesh
          filename="file://$(find description)/meshes/LAExtend_Link.STL" />
      </geometry>
    </collision>
  </link>
  <joint
    name="LApin"
    type="prismatic">
    <origin
      xyz="0.042052 -0.26173 0.40387"
      rpy="-3.1416 0 3.1416" />
    <parent
      link="LA_Link" />
    <child
      link="LAExtend_Link" />
    <axis xyz="0 0 1"/>
      
    <limit
      lower="0"
      upper="0"
      effort="0"
      velocity="0" />
  </joint>
  <link
    name="TLA_Link">
    <inertial>
      <origin
        xyz="0.042052315909939 0.0218514549059929 3.83189571184772E-08"
        rpy="0 0 0" />
      <mass
        value="0.0898377249563407" />
      <inertia
        ixx="0.00063430127231368"
        ixy="-3.23718437638293E-11"
        ixz="-1.23742704915436E-10"
        iyy="4.44119295047454E-06"
        iyz="1.42114603355184E-10"
        izz="0.00063433018916756" />
    </inertial>
    <visual>
      <origin
        xyz="0 0 0"
        rpy="0 0 0" />
      <geometry>
        <mesh
          filename="file://$(find description)/meshes/TLA_Link.STL" />
      </geometry>
      <material
        name="">
        <color
          rgba="0.792156862745098 0.819607843137255 0.933333333333333 1" />
      </material>
    </visual>
    <collision>
      <origin
        xyz="0 0 0"
        rpy="0 0 0" />
      <geometry>
        <mesh
          filename="file://$(find description)/meshes/TLA_Link.STL" />
      </geometry>
    </collision>
  </link>
  <joint
    name="TLApivot"
    type="revolute">
    <origin
      xyz="0 0 0"
      rpy="0 0 0" />
    <parent
      link="LAExtend_Link" />
    <child
      link="TLA_Link" />
    <axis xyz="0 0 1"/>
      
    <limit
      lower="0"
      upper="0"
      effort="0"
      velocity="0" />
  </joint>
  <link
    name="Hopper_Link">
    <inertial>
      <origin
        xyz="-0.219736294416845 -0.0543495810510721 0.24096435760675"
        rpy="0 0 0" />
      <mass
        value="6.54352519463928" />
      <inertia
        ixx="0.236937135700839"
        ixy="-3.42028085939359E-05"
        ixz="-4.38692494852986E-05"
        iyy="0.25276620864523"
        iyz="-0.0027622960057984"
        izz="0.183770300421009" />
    </inertial>
    <visual>
      <origin
        xyz="0 0 0"
        rpy="0 0 0" />
      <geometry>
        <mesh
          filename="file://$(find description)/meshes/Hopper_Link.STL" />
      </geometry>
      <material
        name="">
        <color
          rgba="0.866666666666667 0.909803921568627 1 1" />
      </material>
    </visual>
    <collision>
      <origin
        xyz="0 0 0"
        rpy="0 0 0" />
      <geometry>
        <mesh
          filename="file://$(find description)/meshes/Hopper_Link.STL" />
      </geometry>
    </collision>
  </link>
  <joint
    name="HopperRotate"
    type="revolute">
    <origin
      xyz="0.37173 -1.5824 1.0636"
      rpy="0.03431 1.5708 0" />
    <parent
      link="chassis_link" />
    <child
      link="Hopper_Link" />
    <axis xyz="0 0 1"/>
    <limit
      lower="0"
      upper="0"
      effort="0"
      velocity="0" />
  </joint>
  <link
    name="Excavation_Link">
    <inertial>
      <origin
        xyz="2.97539770599542E-14 -1.48880907602233E-13 0.194999999999999"
        rpy="0 0 0" />
      <mass
        value="0.0165497454663206" />
      <inertia
        ixx="0.000209824338891714"
        ixy="8.470329472543E-22"
        ixz="5.27692874201895E-19"
        iyy="0.000209824338891714"
        iyz="4.90565007579485E-17"
        izz="1.12630212201348E-07" />
    </inertial>
    <visual>
      <origin
        xyz="0 0 0"
        rpy="0 0 0" />
      <geometry>
        <mesh
          filename="file://$(find description)/meshes/Excavation_Link.STL" />
      </geometry>
      <material
        name="">
        <color
          rgba="0.792156862745098 0.819607843137255 0.933333333333333 1" />
      </material>
    </visual>
    <collision>
      <origin
        xyz="0 0 0"
        rpy="0 0 0" />
      <geometry>
        <mesh
          filename="file://$(find description)/meshes/Excavation_Link.STL" />
      </geometry>
    </collision>
  </link>
  <joint
    name="ExcavationRotate"
    type="continuous">
    <origin
      xyz="0 -0.18376 0.47135"
      rpy="1.5708 -0.045099 -1.5708" />
    <parent
      link="Hopper_Link" />
    <child
      link="Excavation_Link" />
    <axis xyz="0 0 1"/>
      
  </joint>
  <link
    name="HopperDoor_Link">
    <inertial>
      <origin
        xyz="0.00511512804298841 0.172901014852912 -0.188897848831479"
        rpy="0 0 0" />
      <mass
        value="0.955015291107596" />
      <inertia
        ixx="0.0180835354788582"
        ixy="8.66065621809038E-05"
        ixz="8.88514841001015E-08"
        iyy="0.0079554850914897"
        iyz="8.31128238594252E-07"
        izz="0.0104107782887016" />
    </inertial>
    <visual>
      <origin
        xyz="0 0 0"
        rpy="0 0 0" />
      <geometry>
        <mesh
          filename="file://$(find description)/meshes/HopperDoor_Link.STL" />
      </geometry>
      <material
        name="">
        <color
          rgba="0.866666666666667 0.909803921568627 1 1" />
      </material>
    </visual>
    <collision>
      <origin
        xyz="0 0 0"
        rpy="0 0 0" />
      <geometry>
        <mesh
          filename="file://$(find description)/meshes/HopperDoor_Link.STL" />
      </geometry>
    </collision>
  </link>
  <joint
    name="HDoorRotate"
    type="revolute">
    <origin
      xyz="-0.39067 0.10314 -0.0253"
      rpy="1.5708 1.5696 -1.5708" />
    <parent
      link="Hopper_Link" />
    <child
      link="HopperDoor_Link" />
    <axis xyz="0 0 1"/>
      
    <limit
      lower="0"
      upper="0"
      effort="0"
      velocity="0" />
  </joint>
  <link
    name="Hopperlatch_Link">
    <inertial>
      <origin
        xyz="0.0141353268111352 0.0366536254235537 0.00510338841916735"
        rpy="0 0 0" />
      <mass
        value="0.043273779837236" />
      <inertia
        ixx="3.50242085840612E-05"
        ixy="1.46801247554554E-05"
        ixz="1.43064392076514E-08"
        iyy="2.96338504024743E-05"
        iyz="-4.6451964040997E-08"
        izz="6.39136126816271E-05" />
    </inertial>
    <visual>
      <origin
        xyz="0 0 0"
        rpy="0 0 0" />
      <geometry>
        <mesh
          filename="file://$(find description)/meshes/Hopperlatch_Link.STL" />
      </geometry>
      <material
        name="">
        <color
          rgba="1 0 1 1" />
      </material>
    </visual>
    <collision>
      <origin
        xyz="0 0 0"
        rpy="0 0 0" />
      <geometry>
        <mesh
          filename="file://$(find description)/meshes/Hopperlatch_Link.STL" />
      </geometry>
    </collision>
  </link>
  <joint
    name="HLatchpivot"
    type="revolute">
    <origin
      xyz="0.034925 -0.026035 -0.16264"
      rpy="3.1416 0 -3.1416" />
    <parent
      link="HopperDoor_Link" />
    <child
      link="Hopperlatch_Link" />
    <axis xyz="0 0 1"/>
      
    <limit
      lower="0"
      upper="0"
      effort="0"
      velocity="0" />
  </joint>
</robot>